<?xml version="1.0" encoding="utf-8"?>
<!-- This URDF was automatically created by SolidWorks to URDF Exporter! Originally created by Stephen Brawner (brawner@gmail.com) 
     Commit Version: 1.6.0-4-g7f85cfe  Build Version: 1.6.7995.38578
     For more information, please see http://wiki.ros.org/sw_urdf_exporter -->
<robot
  name="rod_projekt2">


<!-- Root-Link: "world" -->
<link name="world">
  <inertial>
    <mass value="0.001"/>
    <inertia ixx="0.001" ixy="0" ixz="0" iyy="0.001" iyz="0" izz="0.001"/>
  </inertial>
</link>

<!-- Verbinde "world" mit "baselink" -->
<joint name="world_to_base_joint" type="fixed">
  <parent link="world"/>
  <child link="baselink"/>
  <origin xyz="0 0 0" rpy="0 0 0"/>
</joint>



  <link
    name="baselink">
    <inertial>
      <origin
        xyz="2.4124611990646 1.04377091218881 0.64"
        rpy="0 0 0" />
      <mass
        value="46.1322926928931" />
      <inertia
        ixx="0.490071729660883"
        ixy="3.21899023150044E-18"
        ixz="-8.11670976067688E-20"
        iyy="0.131263595085593"
        iyz="-6.1674335020889E-18"
        izz="0.490071729660883" />
    </inertial>
    <visual>
      <origin
        xyz="0 0 0"
        rpy="0 0 0" />
      <geometry>
        <mesh
          filename="package://rod_projekt2/meshes/baselink.STL" />
      </geometry>
      <material
        name="">
        <color
          rgba="1 1 1 1" />
      </material>
    </visual>
    <collision>
      <origin
        xyz="0 0 0"
        rpy="0 0 0" />
      <geometry>
        <mesh
          filename="package://rod_projekt2/meshes/baselink.STL" />
      </geometry>
    </collision>
  </link>
  <link
    name="scara_basejoint">
    <inertial>
      <origin
        xyz="0.075 0 0.16377"
        rpy="0 0 0" />
      <mass
        value="46.132" />
      <inertia
        ixx="0.49007"
        ixy="9.4154E-20"
        ixz="3.2108E-18"
        iyy="0.49007"
        iyz="5.7519E-18"
        izz="0.13126" />
    </inertial>
    <visual>
      <origin
        xyz="0 0 0"
        rpy="0 0 0" />
      <geometry>
        <mesh
          filename="package://rod_projekt2/meshes/scara_basejoint.STL" />
      </geometry>
      <material
        name="">
        <color
          rgba="1 1 1 1" />
      </material>
    </visual>
    <collision>
      <origin
        xyz="0 0 0"
        rpy="0 0 0" />
      <geometry>
        <mesh
          filename="package://rod_projekt2/meshes/scara_basejoint.STL" />
      </geometry>
    </collision>
  </link>
  <joint
    name="sj0"
    type="fixed">
    <origin
      xyz="2.3374611990646 -0.64 0.88"
      rpy="0 0 0" />
    <parent
      link="baselink" />
    <child
      link="scara_basejoint" />
    <axis
      xyz="0 0 0" />
  </joint>
  <link
    name="scara_j1">
    <inertial>
      <origin
        xyz="0.22082 9.31E-07 0.051377"
        rpy="0 0 0" />
      <mass
        value="49.593" />
      <inertia
        ixx="0.2229"
        ixy="-2.8701E-17"
        ixz="0.073968"
        iyy="0.73689"
        iyz="1.955E-17"
        izz="0.86509" />
    </inertial>
    <visual>
      <origin
        xyz="0 0 0"
        rpy="0 0 0" />
      <geometry>
        <mesh
          filename="package://rod_projekt2/meshes/scara_j1.STL" />
      </geometry>
      <material
        name="">
        <color
          rgba="1 1 1 1" />
      </material>
    </visual>
    <collision>
      <origin
        xyz="0 0 0"
        rpy="0 0 0" />
      <geometry>
        <mesh
          filename="package://rod_projekt2/meshes/scara_j1.STL" />
      </geometry>
    </collision>
  </link>
  <joint
    name="sj1"
    type="revolute">
    <origin
      xyz="0.071834 0 0.375"
      rpy="0 0 0" />
    <parent
      link="scara_basejoint" />
    <child
      link="scara_j1" />
    <axis
      xyz="0 0 1" />
    <limit
      lower="-2.7"
      upper="2.7"
      effort="10000"
      velocity="9.2" />
    <dynamics
      damping="1"
      friction="1" />
  </joint>
  <link
    name="scara_j2">
    <inertial>
      <origin
        xyz="-0.21736 2.0369E-08 -0.084883"
        rpy="0 0 0" />
      <mass
        value="32.585" />
      <inertia
        ixx="0.16446"
        ixy="-2.6672E-07"
        ixz="0.005016"
        iyy="0.37728"
        iyz="1.5574E-07"
        izz="0.32874" />
    </inertial>
    <visual>
      <origin
        xyz="0 0 0"
        rpy="0 0 0" />
      <geometry>
        <mesh
          filename="package://rod_projekt2/meshes/scara_j2.STL" />
      </geometry>
      <material
        name="">
        <color
          rgba="1 1 1 1" />
      </material>
    </visual>
    <collision>
      <origin
        xyz="0 0 0"
        rpy="0 0 0" />
      <geometry>
        <mesh
          filename="package://rod_projekt2/meshes/scara_j2.STL" />
      </geometry>
    </collision>
  </link>
  <joint
    name="sj2"
    type="revolute">
    <origin
      xyz="0.325 0 0.06"
      rpy="3.1416 0 3.1416" />
    <parent
      link="scara_j1" />
    <child
      link="scara_j2" />
    <axis
      xyz="0 0 1" />
    <limit
      lower="-2.7"
      upper="2.7"
      effort="10000"
      velocity="9.2" />
    <dynamics
      damping="1"
      friction="1" />
  </joint>
  <link
    name="scara_j3">
    <inertial>
      <origin
        xyz="-0.01 -1.1102E-16 -0.185"
        rpy="0 0 0" />
      <mass
        value="0.46031" />
      <inertia
        ixx="0.0052628"
        ixy="-2.3008E-35"
        ixz="-5.772E-20"
        iyy="0.0052628"
        iyz="-2.5583E-19"
        izz="2.3015E-05" />
    </inertial>
    <visual>
      <origin
        xyz="0 0 0"
        rpy="0 0 0" />
      <geometry>
        <mesh
          filename="package://rod_projekt2/meshes/scara_j3.STL" />
      </geometry>
      <material
        name="">
        <color
          rgba="1 1 1 1" />
      </material>
    </visual>
    <collision>
      <origin
        xyz="0 0 0"
        rpy="0 0 0" />
      <geometry>
        <mesh
          filename="package://rod_projekt2/meshes/scara_j3.STL" />
      </geometry>
    </collision>
  </link>
  <joint
    name="sj3"
    type="prismatic">
    <origin
      xyz="-0.225 0 0.06926"
      rpy="0 0 0" />
    <parent
      link="scara_j2" />
    <child
      link="scara_j3" />
    <axis
      xyz="0 0 1" />
    <limit
      lower="0"
      upper="0.32"
      effort="10000"
      velocity="2" />
    <dynamics
      damping="1"
      friction="1" />
  </joint>
  <link
    name="scara_jEE">
    <inertial>
      <origin
        xyz="0.011193 0.0086433 0.011596"
        rpy="0 0 0" />
      <mass
        value="0.0073471" />
      <inertia
        ixx="1.5696E-06"
        ixy="-2.647E-22"
        ixz="-7.7943E-22"
        iyy="1.5696E-06"
        iyz="-2.5974E-23"
        izz="2.4657E-06" />
    </inertial>
    <visual>
      <origin
        xyz="0 0 0"
        rpy="0 0 0" />
      <geometry>
        <mesh
          filename="package://rod_projekt2/meshes/scara_jEE.STL" />
      </geometry>
      <material
        name="">
        <color
          rgba="1 1 1 1" />
      </material>
    </visual>
    <collision>
      <origin
        xyz="0 0 0"
        rpy="0 0 0" />
      <geometry>
        <mesh
          filename="package://rod_projekt2/meshes/scara_jEE.STL" />
      </geometry>
    </collision>
  </link>
  <joint
    name="sjEE"
    type="revolute">
    <origin
      xyz="0 0 0"
      rpy="0 0 -3.0137" />
    <parent
      link="scara_j3" />
    <child
      link="scara_jEE" />
    <axis
      xyz="0 0 10" />
    <limit
      lower="-6.2"
      upper="6.2"
      effort="10000"
      velocity="41.9" />
    <dynamics
      damping="1"
      friction="1" />
  </joint>
  <link
    name="sixaxis_joint">
    <inertial>
      <origin
        xyz="-0.18625 0.158 0.14734"
        rpy="0 0 0" />
      <mass
        value="172.39" />
      <inertia
        ixx="2.4169"
        ixy="3.8862E-17"
        ixz="0.040811"
        iyy="2.4528"
        iyz="5.2177E-16"
        izz="1.9871" />
    </inertial>
    <visual>
      <origin
        xyz="0 0 0"
        rpy="0 0 0" />
      <geometry>
        <mesh
          filename="package://rod_projekt2/meshes/sixaxis_joint.STL" />
      </geometry>
      <material
        name="">
        <color
          rgba="1 1 1 1" />
      </material>
    </visual>
    <collision>
      <origin
        xyz="0 0 0"
        rpy="0 0 0" />
      <geometry>
        <mesh
          filename="package://rod_projekt2/meshes/sixaxis_joint.STL" />
      </geometry>
    </collision>
  </link>
  <joint
    name="saj0"
    type="fixed">
    <origin
      xyz="-1.5115388009354 -1.28 0.3"
      rpy="0 0 0" />
    <parent
      link="baselink" />
    <child
      link="sixaxis_joint" />
    <axis
      xyz="0 0 0" />
  </joint>
  <link
    name="sixaxis_j1">
    <inertial>
      <origin
        xyz="0.166407888777253 0.00270619711331221 0.131756348004992"
        rpy="0 0 0" />
      <mass
        value="164.220243766125" />
      <inertia
        ixx="3.1527749049479"
        ixy="0.0229019541898426"
        ixz="0.258298374909936"
        iyy="2.83920937497612"
        iyz="-0.0879512707996945"
        izz="2.5052516173233" />
    </inertial>
    <visual>
      <origin
        xyz="0 0 0"
        rpy="0 0 0" />
      <geometry>
        <mesh
          filename="package://rod_projekt2/meshes/sixaxis_j1.STL" />
      </geometry>
      <material
        name="">
        <color
          rgba="1 1 1 1" />
      </material>
    </visual>
    <collision>
      <origin
        xyz="0 0 0"
        rpy="0 0 0" />
      <geometry>
        <mesh
          filename="package://rod_projekt2/meshes/sixaxis_j1.STL" />
      </geometry>
    </collision>
  </link>
  <joint
    name="saj1"
    type="revolute">
    <origin
      xyz="-0.18117 0.158 0.317"
      rpy="0 0 3.1416" />
    <parent
      link="sixaxis_joint" />
    <child
      link="sixaxis_j1" />
    <axis
      xyz="0 0 1" />
    <limit
      lower="-4.3"
      upper="4.3"
      effort="10000"
      velocity="8" />
    <dynamics
      damping="1"
      friction="1" />
  </joint>
  <link
    name="sixaxis_j2">
    <inertial>
      <origin
        xyz="0.099999995682398 0.258404064748791 -0.00035671799470105"
        rpy="0 0 0" />
      <mass
        value="151.815580162929" />
      <inertia
        ixx="3.13807003006497"
        ixy="7.52213431799499E-08"
        ixz="-3.89620739979185E-07"
        iyy="1.57443223206953"
        iyz="0.102886484823696"
        izz="2.07831344045908" />
    </inertial>
    <visual>
      <origin
        xyz="0 0 0"
        rpy="0 0 0" />
      <geometry>
        <mesh
          filename="package://rod_projekt2/meshes/sixaxis_j2.STL" />
      </geometry>
      <material
        name="">
        <color
          rgba="1 1 1 1" />
      </material>
    </visual>
    <collision>
      <origin
        xyz="0 0 0"
        rpy="0 0 0" />
      <geometry>
        <mesh
          filename="package://rod_projekt2/meshes/sixaxis_j2.STL" />
      </geometry>
    </collision>
  </link>
  <joint
    name="saj2"
    type="revolute">
    <origin
      xyz="-0.054129 -0.002 0.32966"
      rpy="1.5708 0 0" />
    <parent
      link="sixaxis_j1" />
    <child
      link="sixaxis_j2" />
    <axis
      xyz="0 0 1" />
    <limit
      lower="-2"
      upper="2"
      effort="10000"
      velocity="6.6" />
    <dynamics
      damping="1"
      friction="1" />
  </joint>
  <link
    name="sixaxis_j3">
    <inertial>
      <origin
        xyz="0.00477403537382637 0.0140978139883048 -0.113360157742862"
        rpy="0 0 0" />
      <mass
        value="96.5882594701658" />
      <inertia
        ixx="0.992964122192071"
        ixy="0.00372656475176859"
        ixz="-0.00446756292674667"
        iyy="0.882062716412936"
        iyz="-0.0866313255434464"
        izz="0.748146671136659" />
    </inertial>
    <visual>
      <origin
        xyz="0 0 0"
        rpy="0 0 0" />
      <geometry>
        <mesh
          filename="package://rod_projekt2/meshes/sixaxis_j3.STL" />
      </geometry>
      <material
        name="">
        <color
          rgba="1 1 1 1" />
      </material>
    </visual>
    <collision>
      <origin
        xyz="0 0 0"
        rpy="0 0 0" />
      <geometry>
        <mesh
          filename="package://rod_projekt2/meshes/sixaxis_j3.STL" />
      </geometry>
    </collision>
  </link>
  <joint
    name="saj3"
    type="revolute">
    <origin
      xyz="0 0.584 0"
      rpy="-1.5708 0 0" />
    <parent
      link="sixaxis_j2" />
    <child
      link="sixaxis_j3" />
    <axis
      xyz="0 1 0" />
    <limit
      lower="-3.6"
      upper="1"
      effort="10000"
      velocity="4.9" />
    <dynamics
      damping="1"
      friction="1" />
  </joint>
  <link
    name="sixaxis_j4">
    <inertial>
      <origin
        xyz="0.000575031491278022 -1.46367007403114E-09 0.230214046287128"
        rpy="0 0 0" />
      <mass
        value="103.895632295874" />
      <inertia
        ixx="2.36014054037978"
        ixy="4.11178078944612E-07"
        ixz="-0.0166553919102085"
        iyy="2.48389418843073"
        iyz="8.85356435200728E-09"
        izz="0.597811257920955" />
    </inertial>
    <visual>
      <origin
        xyz="0 0 0"
        rpy="0 0 0" />
      <geometry>
        <mesh
          filename="package://rod_projekt2/meshes/sixaxis_j4.STL" />
      </geometry>
      <material
        name="">
        <color
          rgba="1 1 1 1" />
      </material>
    </visual>
    <collision>
      <origin
        xyz="0 0 0"
        rpy="0 0 0" />
      <geometry>
        <mesh
          filename="package://rod_projekt2/meshes/sixaxis_j4.STL" />
      </geometry>
    </collision>
  </link>
  <joint
    name="saj4"
    type="revolute">
    <origin
      xyz="-0.12767 0 0.036"
      rpy="-1.5708 0 1.5708" />
    <parent
      link="sixaxis_j3" />
    <child
      link="sixaxis_j4" />
    <axis
      xyz="0 0 1" />
    <limit
      lower="-7"
      upper="7"
      effort="10000"
      velocity="9.8" />
    <dynamics
      damping="1"
      friction="1" />
  </joint>
  <link
    name="sixaxis_j5">
    <inertial>
      <origin
        xyz="-0.00132228380306176 -0.105473198222159 0.064486899124544"
        rpy="0 0 0" />
      <mass
        value="23.7724316733649" />
      <inertia
        ixx="0.1051788978244"
        ixy="-3.63114897995818E-08"
        ixz="7.90289903055959E-08"
        iyy="0.0644734231624818"
        iyz="0.0017442400121925"
        izz="0.110248713744064" />
    </inertial>
    <visual>
      <origin
        xyz="0 0 0"
        rpy="0 0 0" />
      <geometry>
        <mesh
          filename="package://rod_projekt2/meshes/sixaxis_j5.STL" />
      </geometry>
      <material
        name="">
        <color
          rgba="1 1 1 1" />
      </material>
    </visual>
    <collision>
      <origin
        xyz="0 0 0"
        rpy="0 0 0" />
      <geometry>
        <mesh
          filename="package://rod_projekt2/meshes/sixaxis_j5.STL" />
      </geometry>
    </collision>
  </link>
  <joint
    name="saj5"
    type="revolute">
    <origin
      xyz="0.00010001 -0.02 0.50583"
      rpy="-1.5708 0.017333 -1.5708" />
    <parent
      link="sixaxis_j4" />
    <child
      link="sixaxis_j5" />
    <axis
      xyz="0 0 1" />
    <limit
      lower="-2.2"
      upper="2.1"
      effort="10000"
      velocity="7.3" />
    <dynamics
      damping="1"
      friction="1" />
  </joint>
  <link
    name="sixaxis_j6">
    <inertial>
      <origin
        xyz="-0.000713321367931341 0 0.036266834544977"
        rpy="0 0 0" />
      <mass
        value="2.91352376315292" />
      <inertia
        ixx="0.00448039616987277"
        ixy="-3.76127611298156E-21"
        ixz="8.50421079043318E-18"
        iyy="0.00446708256987277"
        iyz="-2.35027871789775E-19"
        izz="0.00668986164707731" />
    </inertial>
    <visual>
      <origin
        xyz="0 0 0"
        rpy="0 0 0" />
      <geometry>
        <mesh
          filename="package://rod_projekt2/meshes/sixaxis_j6.STL" />
      </geometry>
      <material
        name="">
        <color
          rgba="1 1 1 1" />
      </material>
    </visual>
    <collision>
      <origin
        xyz="0 0 0"
        rpy="0 0 0" />
      <geometry>
        <mesh
          filename="package://rod_projekt2/meshes/sixaxis_j6.STL" />
      </geometry>
    </collision>
  </link>
  <joint
    name="saj6"
    type="revolute">
    <origin
      xyz="0 -0.141 0"
      rpy="1.5708 0 0" />
    <parent
      link="sixaxis_j5" />
    <child
      link="sixaxis_j6" />
    <axis
      xyz="0 0 1" />
    <limit
      lower="-14"
      upper="14"
      effort="10000"
      velocity="13.1" />
    <dynamics
      damping="1"
      friction="1" />
  </joint>



  <link
    name="sixaxis_jGripper1">
    <inertial>
      <origin
        xyz="0 0 0"
        rpy="0 0 0" />
      <mass
        value="0.5024" />
      <inertia
        ixx="0.0042"
        ixy="0"
        ixz="0"
        iyy="0.0017"
        iyz="0"
        izz="0.0021" />
    </inertial>
    <visual>
      <origin
        xyz="0 0 0"
        rpy="0 0 0" />
      <geometry>
        <mesh
          filename="package://rod_projekt2/meshes/sixaxis_jGripper1.STL" />
      </geometry>
      <material
        name="">
        <color
          rgba="1 1 1 1" />
      </material>
    </visual>
    <collision>
      <origin
        xyz="0 0 0"
        rpy="0 0 0" />
      <geometry>
        <mesh
          filename="package://rod_projekt2/meshes/sixaxis_jGripper1.STL" />
      </geometry>
    </collision>
  </link>
  <joint
    name="saEE1"
    type="prismatic">
    <origin
      xyz="-0.03 -0.014 -0.02"
      rpy="0 0 3.1416" />
    <parent
      link="sixaxis_j6" />
    <child
      link="sixaxis_jGripper1" />
    <axis
      xyz="1 0 0" />
    <limit
      lower="-0.02"
      upper="0"
      effort="10000"
      velocity="3.14" />
    <dynamics
      damping="1"
      friction="1" />
  </joint>
  <link
    name="sixaxis_jGripper2">
    <inertial>
      <origin
        xyz="0 0 0"
        rpy="0 0 0" />
      <mass
        value="0.5024" />
      <inertia
        ixx="0.0042"
        ixy="0"
        ixz="0"
        iyy="0.0017"
        iyz="0"
        izz="0.0021" />
    </inertial>
    <visual>
      <origin
        xyz="0 0 0"
        rpy="0 0 0" />
      <geometry>
        <mesh
          filename="package://rod_projekt2/meshes/sixaxis_jGripper2.STL" />
      </geometry>
      <material
        name="">
        <color
          rgba="1 1 1 1" />
      </material>
    </visual>
    <collision>
      <origin
        xyz="0 0 0"
        rpy="0 0 0" />
      <geometry>
        <mesh
          filename="package://rod_projekt2/meshes/sixaxis_jGripper2.STL" />
      </geometry>
    </collision>
  </link>
  <joint
    name="saEE2"
    type="prismatic">
    <origin
      xyz="0.03 0.014 -0.02"
      rpy="0 0 0" />
    <parent
      link="sixaxis_j6" />
    <child
      link="sixaxis_jGripper2" />
    <axis
      xyz="1 0 0" />
    <limit
      lower="0"
      upper="0.02"
      effort="10000"
      velocity="3.14" />
    <dynamics
      damping="1"
      friction="1" />
  </joint>



  <link
    name="conveyor1_joint">
    <inertial>
      <origin
        xyz="0.175 0.0218 -0.81251"
        rpy="0 0 0" />
      <mass
        value="64.823" />
      <inertia
        ixx="69.361"
        ixy="7.6248E-17"
        ixz="6.1052E-15"
        iyy="68.535"
        iyz="0.0012967"
        izz="1.3786" />
    </inertial>
    <visual>
      <origin
        xyz="0 0 0"
        rpy="0 0 0" />
      <geometry>
        <mesh
          filename="package://rod_projekt2/meshes/conveyor1_joint.STL" />
      </geometry>
      <material
        name="">
        <color
          rgba="1 1 1 1" />
      </material>
    </visual>
    <collision>
      <origin
        xyz="0 0 0"
        rpy="0 0 0" />
      <geometry>
        <mesh
          filename="package://rod_projekt2/meshes/conveyor1_joint.STL" />
      </geometry>
    </collision>
  </link>


  <joint
    name="c1"
    type="fixed">
    <origin
      xyz="0 -1.26 0.98"
      rpy="-1.5708 0 1.5708" />
    <parent
      link="baselink" />
    <child
      link="conveyor1_joint" />
    <axis
      xyz="0 0 0" />
  </joint>
  <link
    name="conveyor2_joint">
    <inertial>
      <origin
        xyz="0.175 -2.053 0.0218"
        rpy="0 0 0" />
      <mass
        value="64.823" />
      <inertia
        ixx="69.361"
        ixy="-2.9977E-15"
        ixz="4.8068E-18"
        iyy="1.3786"
        iyz="0.0012967"
        izz="68.535" />
    </inertial>
    <visual>
      <origin
        xyz="0 0 0"
        rpy="0 0 0" />
      <geometry>
        <mesh
          filename="package://rod_projekt2/meshes/conveyor2_joint.STL" />
      </geometry>
      <material
        name="">
        <color
          rgba="1 1 1 1" />
      </material>
    </visual>
    <collision>
      <origin
        xyz="0 0 0"
        rpy="0 0 0" />
      <geometry>
        <mesh
          filename="package://rod_projekt2/meshes/conveyor2_joint.STL" />
      </geometry>
    </collision>
  </link>
  <joint
    name="c2"
    type="fixed">
    <origin
      xyz="1.8595 -0.02 0.98"
      rpy="3.1416 0 -1.5708" />
    <parent
      link="baselink" />
    <child
      link="conveyor2_joint" />
    <axis
      xyz="0 0 0" />
  </joint>
  <link
    name="scarasocket_joint">
    <inertial>
      <origin
        xyz="0.1 0.44 0"
        rpy="0 0 0" />
      <mass
        value="35.2" />
      <inertia
        ixx="2.3889"
        ixy="-1.7526E-34"
        ixz="1.2064E-17"
        iyy="0.23467"
        iyz="3.7117E-32"
        izz="2.3889" />
    </inertial>
    <visual>
      <origin
        xyz="0 0 0"
        rpy="0 0 0" />
      <geometry>
        <mesh
          filename="package://rod_projekt2/meshes/scarasocket_joint.STL" />
      </geometry>
      <material
        name="">
        <color
          rgba="1 1 1 1" />
      </material>
    </visual>
    <collision>
      <origin
        xyz="0 0 0"
        rpy="0 0 0" />
      <geometry>
        <mesh
          filename="package://rod_projekt2/meshes/scarasocket_joint.STL" />
      </geometry>
    </collision>
  </link>
  <joint
    name="sb"
    type="fixed">
    <origin
      xyz="2.3125 -0.64 0"
      rpy="1.5708 0 0" />
    <parent
      link="baselink" />
    <child
      link="scarasocket_joint" />
    <axis
      xyz="0 0 0" />
  </joint>
  <link
    name="sixaxissocket">
    <inertial>
      <origin
        xyz="-0.25 0.15 0"
        rpy="0 0 0" />
      <mass
        value="58.905" />
      <inertia
        ixx="1.3622"
        ixy="-4.2687E-33"
        ixz="0"
        iyy="1.8408"
        iyz="-6.0185E-33"
        izz="1.3622" />
    </inertial>
    <visual>
      <origin
        xyz="0 0 0"
        rpy="0 0 0" />
      <geometry>
        <mesh
          filename="package://rod_projekt2/meshes/sixaxissocket.STL" />
      </geometry>
      <material
        name="">
        <color
          rgba="1 1 1 1" />
      </material>
    </visual>
    <collision>
      <origin
        xyz="0 0 0"
        rpy="0 0 0" />
      <geometry>
        <mesh
          filename="package://rod_projekt2/meshes/sixaxissocket.STL" />
      </geometry>
    </collision>
  </link>
  <joint
    name="sab"
    type="fixed">
    <origin
      xyz="-1.4345388009354 -1.122 0"
      rpy="1.5707963267949 0 0" />
    <parent
      link="baselink" />
    <child
      link="sixaxissocket" />
    <axis
      xyz="0 0 0" />
  </joint>


  <transmission name="trans_saj1">
        <type>transmission_interface/SimpleTransmission</type>
        <joint name="saj1">
            <hardwareInterface>hardware_interface/PositionJointInterface</hardwareInterface>
        </joint>
        <actuator name="saj1_motor">
            <hardwareInterface>hardware_interface/PositionJointInterface</hardwareInterface>
            <mechanicalReduction>1</mechanicalReduction>
        </actuator>
    </transmission>
    <transmission name="trans_saj2">
        <type>transmission_interface/SimpleTransmission</type>
        <joint name="saj2">
            <hardwareInterface>hardware_interface/PositionJointInterface</hardwareInterface>
        </joint>
        <actuator name="saj2_motor">
            <hardwareInterface>hardware_interface/PositionJointInterface</hardwareInterface>
            <mechanicalReduction>1</mechanicalReduction>
        </actuator>
    </transmission>
    <transmission name="trans_saj3">
        <type>transmission_interface/SimpleTransmission</type>
        <joint name="saj3">
            <hardwareInterface>hardware_interface/PositionJointInterface</hardwareInterface>
        </joint>
        <actuator name="saj3_motor">
            <hardwareInterface>hardware_interface/PositionJointInterface</hardwareInterface>
            <mechanicalReduction>1</mechanicalReduction>
        </actuator>
    </transmission>
    <transmission name="trans_saj4">
        <type>transmission_interface/SimpleTransmission</type>
        <joint name="saj4">
            <hardwareInterface>hardware_interface/PositionJointInterface</hardwareInterface>
        </joint>
        <actuator name="saj4_motor">
            <hardwareInterface>hardware_interface/PositionJointInterface</hardwareInterface>
            <mechanicalReduction>1</mechanicalReduction>
        </actuator>
    </transmission>
    <transmission name="trans_saj5">
        <type>transmission_interface/SimpleTransmission</type>
        <joint name="saj5">
            <hardwareInterface>hardware_interface/PositionJointInterface</hardwareInterface>
        </joint>
        <actuator name="saj5_motor">
            <hardwareInterface>hardware_interface/PositionJointInterface</hardwareInterface>
            <mechanicalReduction>1</mechanicalReduction>
        </actuator>
    </transmission>
    <transmission name="trans_saj6">
        <type>transmission_interface/SimpleTransmission</type>
        <joint name="saj6">
            <hardwareInterface>hardware_interface/PositionJointInterface</hardwareInterface>
        </joint>
        <actuator name="saj6_motor">
            <hardwareInterface>hardware_interface/PositionJointInterface</hardwareInterface>
            <mechanicalReduction>1</mechanicalReduction>
        </actuator>
    </transmission>
<!-- Transmission für Sixaxis-Greifer 1 -->
<transmission name="trans_saEE1">
  <type>transmission_interface/SimpleTransmission</type>
  <joint name="saEE1">
    <hardwareInterface>hardware_interface/PositionJointInterface</hardwareInterface>
  </joint>
  <actuator name="saEE1_motor">
    <hardwareInterface>hardware_interface/PositionJointInterface</hardwareInterface>
    <mechanicalReduction>1</mechanicalReduction>
  </actuator>
</transmission>

<!-- Transmission für Sixaxis-Greifer 2 -->
<transmission name="trans_saEE2">
  <type>transmission_interface/SimpleTransmission</type>
  <joint name="saEE2">
    <hardwareInterface>hardware_interface/PositionJointInterface</hardwareInterface>
  </joint>
  <actuator name="saEE2_motor">
    <hardwareInterface>hardware_interface/PositionJointInterface</hardwareInterface>
    <mechanicalReduction>1</mechanicalReduction>
  </actuator>
</transmission>






<transmission name="trans_sj1">
        <type>transmission_interface/SimpleTransmission</type>
        <joint name="sj1">
            <hardwareInterface>hardware_interface/PositionJointInterface</hardwareInterface>
        </joint>
        <actuator name="sj1_motor">
            <hardwareInterface>hardware_interface/PositionJointInterface</hardwareInterface>
            <mechanicalReduction>1</mechanicalReduction>
        </actuator>
    </transmission>
    <transmission name="trans_sj2">
        <type>transmission_interface/SimpleTransmission</type>
        <joint name="sj2">
            <hardwareInterface>hardware_interface/PositionJointInterface</hardwareInterface>
        </joint>
        <actuator name="sj2_motor">
            <hardwareInterface>hardware_interface/PositionJointInterface</hardwareInterface>
            <mechanicalReduction>1</mechanicalReduction>
        </actuator>
    </transmission>
    <transmission name="trans_sj3">
        <type>transmission_interface/SimpleTransmission</type>
        <joint name="sj3">
            <hardwareInterface>hardware_interface/PositionJointInterface</hardwareInterface>
        </joint>
        <actuator name="sj3_motor">
            <hardwareInterface>hardware_interface/PositionJointInterface</hardwareInterface>
            <mechanicalReduction>1</mechanicalReduction>
        </actuator>
    </transmission>
    <transmission name="trans_sjEE">
        <type>transmission_interface/SimpleTransmission</type>
        <joint name="sjEE">
            <hardwareInterface>hardware_interface/PositionJointInterface</hardwareInterface>
        </joint>
        <actuator name="sjEE_motor">
            <hardwareInterface>hardware_interface/PositionJointInterface</hardwareInterface>
            <mechanicalReduction>1</mechanicalReduction>
        </actuator>
    </transmission>


 

    <!-- In der URDF: Gazebo-Plugin mit Namespace -->
    <gazebo>
    <!--
        <plugin name="scara_control" filename="libgazebo_ros_control.so">
            <robotNamespace>/scara</robotNamespace>
        </plugin>
        <plugin name="sixaxis_control" filename="libgazebo_ros_control.so">
            <robotNamespace>/sixaxis</robotNamespace>
        </plugin>
        -->
        <plugin name="gazebo_ros_control" filename="libgazebo_ros_control.so">
            <robotNamespace>/</robotNamespace>
        </plugin>
    </gazebo>

    <gazebo>
        <plugin name = "joint_state_publisher" filename = "libgazebo_ros_joint_state_publisher.so" >
		<jointName>sj1, sj2, sj3, sjEE, saj1, saj2, saj3, saj4, saj5, saj6, saEE1, saEE2</jointName>
        </plugin>
    </gazebo>


</robot>