<?xml version="1.0" encoding="utf-8"?>
<!-- This URDF was automatically created by SolidWorks to URDF Exporter! Originally created by Stephen Brawner (brawner@gmail.com) 
     Commit Version: 1.6.0-4-g7f85cfe  Build Version: 1.6.7995.38578
     For more information, please see http://wiki.ros.org/sw_urdf_exporter -->
<robot
  name="six_axis_robot_urdf1">
  <link
    name="base_link">
    <inertial>
      <origin
        xyz="0.0798745788359631 -0.079 0.0736715388774331"
        rpy="0 0 0" />
      <mass
        value="2.74509771064634" />
      <inertia
        ixx="0.0096215758113607"
        ixy="-3.60982518941985E-19"
        ixz="0.000162466125610687"
        iyy="0.00976445376581624"
        iyz="6.34863574640816E-19"
        izz="0.00791025691621762" />
    </inertial>
    <visual>
      <origin
        xyz="0 0 0"
        rpy="0 0 0" />
      <geometry>
        <mesh
          filename="package://six_axis_robot_urdf1/meshes/base_link.STL" />
      </geometry>
      <material
        name="">
        <color
          rgba="0.792156862745098 0.819607843137255 0.933333333333333 1" />
      </material>
    </visual>
    <collision>
      <origin
        xyz="0 0 0"
        rpy="0 0 0" />
      <geometry>
        <mesh
          filename="package://six_axis_robot_urdf1/meshes/base_link.STL" />
      </geometry>
    </collision>
  </link>
  <link
    name="joint_1">
    <inertial>
      <origin
        xyz="-0.00129605487991559 0.00135309809802346 0.0658781737081199"
        rpy="0 0 0" />
      <mass
        value="2.61497204364903" />
      <inertia
        ixx="0.0125508556232017"
        ixy="9.11703137730301E-05"
        ixz="0.00102825782583604"
        iyy="0.0113025849635249"
        iyz="-0.00035012453581269"
        izz="0.0099731354243766" />
    </inertial>
    <visual>
      <origin
        xyz="0 0 0"
        rpy="0 0 0" />
      <geometry>
        <mesh
          filename="package://six_axis_robot_urdf1/meshes/joint_1.STL" />
      </geometry>
      <material
        name="">
        <color
          rgba="0.792156862745098 0.819607843137255 0.933333333333333 1" />
      </material>
    </visual>
    <collision>
      <origin
        xyz="0 0 0"
        rpy="0 0 0" />
      <geometry>
        <mesh
          filename="package://six_axis_robot_urdf1/meshes/joint_1.STL" />
      </geometry>
    </collision>
  </link>
  <joint
    name="arm_1"
    type="revolute">
    <origin
      xyz="0.084 -0.079 0.1585"
      rpy="0 0 3.1416" />
    <parent
      link="base_link" />
    <child
      link="joint_1" />
    <axis
      xyz="0 0 1" />
    <limit
      lower="-4"
      upper="4"
      effort="10000"
      velocity="1" />
    <dynamics
      damping="0.2"
      friction="0.5" />
  </joint>
  <link
    name="joint_2">
    <inertial>
      <origin
        xyz="-2.1588010268303E-09 0.129202032374396 -0.000178358997350511"
        rpy="0 0 0" />
      <mass
        value="2.41744554399568" />
      <inertia
        ixx="0.0124923169986663"
        ixy="2.99448023717225E-10"
        ixz="-1.55103797626974E-09"
        iyy="0.00626764423594557"
        iyz="0.000409579955508348"
        izz="0.00827354076615877" />
    </inertial>
    <visual>
      <origin
        xyz="0 0 0"
        rpy="0 0 0" />
      <geometry>
        <mesh
          filename="package://six_axis_robot_urdf1/meshes/joint_2.STL" />
      </geometry>
      <material
        name="">
        <color
          rgba="0.792156862745098 0.819607843137255 0.933333333333333 1" />
      </material>
    </visual>
    <collision>
      <origin
        xyz="0 0 0"
        rpy="0 0 0" />
      <geometry>
        <mesh
          filename="package://six_axis_robot_urdf1/meshes/joint_2.STL" />
      </geometry>
    </collision>
  </link>
  <joint
    name="arm_2"
    type="revolute">
    <origin
      xyz="-0.027064 -0.001 0.16483"
      rpy="1.5708 0 0" />
    <parent
      link="joint_1" />
    <child
      link="joint_2" />
    <axis
      xyz="0 0 1" />
    <limit
      lower="-2"
      upper="2"
      effort="10000"
      velocity="1" />
    <dynamics
      damping="0.2"
      friction="0.5" />
  </joint>
  <link
    name="joint_3">
    <inertial>
      <origin
        xyz="0.00238701700038138 0.0177199774720578 -0.00783206709146609"
        rpy="0 0 0" />
      <mass
        value="1.53802960939755" />
      <inertia
        ixx="0.00395288265203851"
        ixy="1.48350507634032E-05"
        ixz="-1.77848842625229E-05"
        iyy="0.00351139616406424"
        iyz="-0.000344869926526457"
        izz="0.00297829088828289" />
    </inertial>
    <visual>
      <origin
        xyz="0 0 0"
        rpy="0 0 0" />
      <geometry>
        <mesh
          filename="package://six_axis_robot_urdf1/meshes/joint_3.STL" />
      </geometry>
      <material
        name="">
        <color
          rgba="0.792156862745098 0.819607843137255 0.933333333333333 1" />
      </material>
    </visual>
    <collision>
      <origin
        xyz="0 0 0"
        rpy="0 0 0" />
      <geometry>
        <mesh
          filename="package://six_axis_robot_urdf1/meshes/joint_3.STL" />
      </geometry>
    </collision>
  </link>
  <joint
    name="arm_3"
    type="revolute">
    <origin
      xyz="0 0.278 0"
      rpy="0 -1.5708 0.21508" />
    <parent
      link="joint_2" />
    <child
      link="joint_3" />
    <axis
      xyz="1 0 0" />
    <limit
      lower="-3.6"
      upper="1"
      effort="10000"
      velocity="1" />
    <dynamics
      damping="0.2"
      friction="0.5" />
  </joint>
  <link
    name="joint_4">
    <inertial>
      <origin
        xyz="0.000287515515776868 -7.60105534070021E-10 0.115107022990382"
        rpy="0 0 0" />
      <mass
        value="1.65438905910093" />
      <inertia
        ixx="0.00939546422129685"
        ixy="1.53548929500136E-09"
        ixz="-6.63031405657805E-05"
        iyy="0.0098881139468349"
        iyz="-2.80873656991026E-10"
        izz="0.00237982179759152" />
    </inertial>
    <visual>
      <origin
        xyz="0 0 0"
        rpy="0 0 0" />
      <geometry>
        <mesh
          filename="package://six_axis_robot_urdf1/meshes/joint_4.STL" />
      </geometry>
      <material
        name="">
        <color
          rgba="0.792156862745098 0.819607843137255 0.933333333333333 1" />
      </material>
    </visual>
    <collision>
      <origin
        xyz="0 0 0"
        rpy="0 0 0" />
      <geometry>
        <mesh
          filename="package://six_axis_robot_urdf1/meshes/joint_4.STL" />
      </geometry>
    </collision>
  </link>
  <joint
    name="arm_4"
    type="revolute">
    <origin
      xyz="0 0.044548 0.053986"
      rpy="0.21508 0 3.1416" />
    <parent
      link="joint_3" />
    <child
      link="joint_4" />
    <axis
      xyz="0 0 1" />
    <limit
      lower="-4"
      upper="4"
      effort="10000"
      velocity="1" />
    <dynamics
      damping="0.2"
      friction="0.5" />
  </joint>
  <link
    name="joint_5">
    <inertial>
      <origin
        xyz="-7.33958749332686E-09 -0.0145979955728184 -0.00125655043772784"
        rpy="0 0 0" />
      <mass
        value="0.37854190562683" />
      <inertia
        ixx="0.000418705803441084"
        ixy="-1.44552108077641E-10"
        ixz="3.1460585320023E-10"
        iyy="0.000256661716411154"
        iyz="6.94363062178592E-06"
        izz="0.000438888191656305" />
    </inertial>
    <visual>
      <origin
        xyz="0 0 0"
        rpy="0 0 0" />
      <geometry>
        <mesh
          filename="package://six_axis_robot_urdf1/meshes/joint_5.STL" />
      </geometry>
      <material
        name="">
        <color
          rgba="0.792156862745098 0.819607843137255 0.933333333333333 1" />
      </material>
    </visual>
    <collision>
      <origin
        xyz="0 0 0"
        rpy="0 0 0" />
      <geometry>
        <mesh
          filename="package://six_axis_robot_urdf1/meshes/joint_5.STL" />
      </geometry>
    </collision>
  </link>
  <joint
    name="arm_5"
    type="revolute">
    <origin
      xyz="0 0 0.2545"
      rpy="-1.5708 0.017333 -1.5708" />
    <parent
      link="joint_4" />
    <child
      link="joint_5" />
    <axis
      xyz="0 0 1" />
    <limit
      lower="-2.2"
      upper="2.1"
      effort="10000"
      velocity="1" />
    <dynamics
      damping="0.2"
      friction="0.5" />
  </joint>
  <link
    name="joint_6">
    <inertial>
      <origin
        xyz="1.11022302462516E-16 -8.32667268468867E-17 0.0238565916677733"
        rpy="0 0 0" />
      <mass
        value="0.0623936904960656" />
      <inertia
        ixx="2.09776386804914E-05"
        ixy="1.74999999999999E-07"
        ixz="-1.18849310411619E-20"
        iyy="2.21246386804914E-05"
        iyz="-2.58452582392193E-21"
        izz="2.84482815037578E-05" />
    </inertial>
    <visual>
      <origin
        xyz="0 0 0"
        rpy="0 0 0" />
      <geometry>
        <mesh
          filename="package://six_axis_robot_urdf1/meshes/joint_6.STL" />
      </geometry>
      <material
        name="">
        <color
          rgba="0.792156862745098 0.819607843137255 0.933333333333333 1" />
      </material>
    </visual>
    <collision>
      <origin
        xyz="0 0 0"
        rpy="0 0 0" />
      <geometry>
        <mesh
          filename="package://six_axis_robot_urdf1/meshes/joint_6.STL" />
      </geometry>
    </collision>
  </link>
  <joint
    name="arm_6"
    type="revolute">
    <origin
      xyz="0 -0.049316 0"
      rpy="1.5708 0 0" />
    <parent
      link="joint_5" />
    <child
      link="joint_6" />
    <axis
      xyz="0 0 1" />
    <limit
      lower="-7"
      upper="7"
      effort="10000"
      velocity="1" />
    <dynamics
      damping="0.2"
      friction="0.5" />
  </joint>
  <link
    name="Gripper1">
    <inertial>
      <origin
        xyz="-0.0212499999999998 -0.00574999999999992 0.0280198952400817"
        rpy="0 0 0" />
      <mass
        value="0.00799999999999998" />
      <inertia
        ixx="1.57083333333333E-06"
        ixy="8.74999999999993E-08"
        ixz="7.74999999999996E-07"
        iyy="2.17083333333332E-06"
        iyz="-1.74999999999999E-07"
        izz="9.08333333333329E-07" />
    </inertial>
    <visual>
      <origin
        xyz="0 0 0"
        rpy="0 0 0" />
      <geometry>
        <mesh
          filename="package://six_axis_robot_urdf1/meshes/Gripper1.STL" />
      </geometry>
      <material
        name="">
        <color
          rgba="0.792156862745098 0.819607843137255 0.933333333333333 1" />
      </material>
    </visual>
    <collision>
      <origin
        xyz="0 0 0"
        rpy="0 0 0" />
      <geometry>
        <mesh
          filename="package://six_axis_robot_urdf1/meshes/Gripper1.STL" />
      </geometry>
    </collision>
  </link>
  <joint
    name="Zange1"
    type="prismatic">
    <origin
      xyz="0 0 0.010664"
      rpy="0 0 3.1416" />
    <parent
      link="joint_6" />
    <child
      link="Gripper1" />
    <axis
      xyz="1 0 0" />
    <limit
      lower="0"
      upper="0"
      effort="0"
      velocity="0" />
  </joint>
  <link
    name="Gripper2">
    <inertial>
      <origin
        xyz="-0.02125 -0.00575000000000007 0.0280198952400818"
        rpy="0 0 0" />
      <mass
        value="0.00800000000000002" />
      <inertia
        ixx="1.57083333333334E-06"
        ixy="8.75E-08"
        ixz="7.74999999999999E-07"
        iyy="2.17083333333333E-06"
        iyz="-1.75E-07"
        izz="9.08333333333333E-07" />
    </inertial>
    <visual>
      <origin
        xyz="0 0 0"
        rpy="0 0 0" />
      <geometry>
        <mesh
          filename="package://six_axis_robot_urdf1/meshes/Gripper2.STL" />
      </geometry>
      <material
        name="">
        <color
          rgba="0.792156862745098 0.819607843137255 0.933333333333333 1" />
      </material>
    </visual>
    <collision>
      <origin
        xyz="0 0 0"
        rpy="0 0 0" />
      <geometry>
        <mesh
          filename="package://six_axis_robot_urdf1/meshes/Gripper2.STL" />
      </geometry>
    </collision>
  </link>
  <joint
    name="Zang2"
    type="prismatic">
    <origin
      xyz="0 0 0"
      rpy="0 0 3.1416" />
    <parent
      link="Gripper1" />
    <child
      link="Gripper2" />
    <axis
      xyz="1 0 0" />
    <limit
      lower="0"
      upper="0"
      effort="0"
      velocity="0" />
  </joint>
</robot>